Workbook

Sheet Data
A1: Year | B1: Industry | C1: State | D1: Establishments | E1: Employees | F1: Avg Annual Wage
A2: 2020 | B2: Natural Resources | C2: Alabama | D2: 1829 | E2: 18051 | F2: 58872
A3: 2020 | B3: Natural Resources | C3: Arizona | D3: 1354 | E3: 35607 | F3: 55216
A4: 2020 | B4: Natural Resources | C4: Arkansas | D4: 2565 | E4: 15961 | F4: 49909
A5: 2020 | B5: Natural Resources | C5: California | D5: 17651 | E5: 425665 | F5: 42534
A6: 2020 | B6: Natural Resources | C6: Colorado | D6: 3312 | E6: 41633 | F6: 91879
A7: 2020 | B7: Natural Resources | C7: Connecticut | D7: 467 | E7: 5260 | F7: 43142
A8: 2020 | B8: Natural Resources | C8: Delaware | D8: 186 | E8: 1317 | F8: 43290
A9: 2020 | B9: Natural Resources | C9: Florida | D9: 5394 | E9: 71107 | F9: 37717
A10: 2020 | B10: Natural Resources | C10: Georgia | D10: 2794 | E10: 29309 | F10: 45978
A11: 2020 | B11: Natural Resources | C11: Idaho | D11: 2531 | E11: 27020 | F11: 42820
A12: 2020 | B12: Natural Resources | C12: Illinois | D12: 2818 | E12: 24933 | F12: 52259
A13: 2020 | B13: Natural Resources | C13: Indiana | D13: 2302 | E13: 20872 | F13: 50732
... A1919: 2017 | B1919: Other Services | C1919: Wyoming | D1919: 1656 | E1919: 7231 | F1919: 35035

Sheet Dashboard
B3: {=INDEX('Data prep'!$E$3:$E$12,11-Dashboard!$A$4)} -> Construction
A4: 6 | I4: 1

Sheet Data prep
A1: INDUSTRY FILTER | E1: AVG WAGE BY INDUSTRY | I1: EMPLOYEES BY INDUSTRY FOR CURRENT YEAR | M1: WAGE & EMPLOYEE TRENDS | T1: COMPARISONS BY STATE FOR CURRENT YEAR & SELECTED INDUSTRY | Z1: Helper dynamic column
A2: Industry | B2: Selection | D2: Index | E2: Industry | F2: Avg Annual wage | G2: Selection | I2: Industry | J2: Employees | M2: Year | N2: Avg wages | O2: Employees | T2: State | U2: Employees | W2: Population | X2: Employees per 1000 Capita | Y2: Average wages | Z2: =B31 -> Average wages | AA2: Linked connection for population
A3: Business Services | B3: =Dashboard!B3 -> Construction | D3: 1 | E3: Information | F3: =AVERAGEIFS(Data!$F:$F,Data!$A:$A,$B$27,Data!$B:$B,$E3) -> 93586.333 | G3: =IF($E3=$B$3,$F3,0) -> 0 | I3: Trade & Transportation | J3: =SUMIFS(Data!$E:$E,Data!$A:$A,$B$27,Data!$B:$B,$I3) -> 26277342 | M3: 2017 | N3: =AVERAGEIFS(Data!$F:$F,Data!$A:$A,$M3,Data!$B:$B,$B$3) -> 57353.83 | O3: =SUMIFS(Data!$E:$E,Data!$A:$A,$M3,Data!$B:$B,$B$3) -> 6834462 | T3: Alabama | U3: =SUMIFS(Data!$E:$E,Data!$A:$A,$B$27,Data!$C:$C,$T3,Data!$B:$B,$B$3) -> 92772 | W3: 5157699 | X3: =U3/W3*1000 -> 17.987091 | Y3: =AVERAGEIFS(Data!$F:$F,Data!$A:$A,$B$27,Data!$B:$B,$B$3,Data!$C:$C,$T3) -> 59279 | Z3: =IF($Z$2=$Y$2,-$Y3,$X3) -> -59279 | AA3: #VALUE! | AB3: {=_FV(AA3,"Population")} -> 5157699
A4: Construction | D4: 2 | E4: Finance | F4: =AVERAGEIFS(Data!$F:$F,Data!$A:$A,$B$27,Data!$B:$B,$E4) -> 90040.667 | G4: =IF($E4=$B$3,$F4,0) -> 0 | I4: Education & Health | J4: =SUMIFS(Data!$E:$E,Data!$A:$A,$B$27,Data!$B:$B,$I4) -> 22035033 | M4: 2018 | N4: =AVERAGEIFS(Data!$F:$F,Data!$A:$A,$M4,Data!$B:$B,$B$3) -> 59438.812 | O4: =SUMIFS(Data!$E:$E,Data!$A:$A,$M4,Data!$B:$B,$B$3) -> 7158459 | T4: Arizona | U4: =SUMIFS(Data!$E:$E,Data!$A:$A,$B$27,Data!$C:$C,$T4,Data!$B:$B,$B$3) -> 173852 | W4: 7582384 | X4: =U4/W4*1000 -> 22.928409 | Y4: =AVERAGEIFS(Data!$F:$F,Data!$A:$A,$B$27,Data!$B:$B,$B$3,Data!$C:$C,$T4) -> 63056 | Z4: =IF($Z$2=$Y$2,-$Y4,$X4) -> -63056 | AA4: #VALUE! | AB4: {=_FV(AA4,"Population")} -> 7582384
A5: Education & Health | D5: 3 | E5: Business Services | F5: =AVERAGEIFS(Data!$F:$F,Data!$A:$A,$B$27,Data!$B:$B,$E5) -> 74713.062 | G5: =IF($E5=$B$3,$F5,0) -> 0 | I5: Business Services | J5: =SUMIFS(Data!$E:$E,Data!$A:$A,$B$27,Data!$B:$B,$I5) -> 20065896 | M5: 2019 | N5: =AVERAGEIFS(Data!$F:$F,Data!$A:$A,$M5,Data!$B:$B,$B$3) -> 61382.208 | O5: =SUMIFS(Data!$E:$E,Data!$A:$A,$M5,Data!$B:$B,$B$3) -> 7383280 | T5: Arkansas | U5: =SUMIFS(Data!$E:$E,Data!$A:$A,$B$27,Data!$C:$C,$T5,Data!$B:$B,$B$3) -> 53142 | W5: 3088354 | X5: =U5/W5*1000 -> 17.207224 | Y5: =AVERAGEIFS(Data!$F:$F,Data!$A:$A,$B$27,Data!$B:$B,$B$3,Data!$C:$C,$T5) -> 52247 | Z5: =IF($Z$2=$Y$2,-$Y5,$X5) -> -52247 | AA5: #VALUE! | AB5: {=_FV(AA5,"Population")} -> 3088354
A6: Finance | D6: 4 | E6: Manufacturing | F6: =AVERAGEIFS(Data!$F:$F,Data!$A:$A,$B$27,Data!$B:$B,$E6) -> 68427.875 | G6: =IF($E6=$B$3,$F6,0) -> 0 | I6: Leisure & Hospitality | J6: =SUMIFS(Data!$E:$E,Data!$A:$A,$B$27,Data!$B:$B,$I6) -> 12649500 | M6: 2020 | N6: =AVERAGEIFS(Data!$F:$F,Data!$A:$A,$M6,Data!$B:$B,$B$3) -> 63896.896 | O6: =SUMIFS(Data!$E:$E,Data!$A:$A,$M6,Data!$B:$B,$B$3) -> 7136444 | T6: California | U6: =SUMIFS(Data!$E:$E,Data!$A:$A,$B$27,Data!$C:$C,$T6,Data!$B:$B,$B$3) -> 855879 | W6: 39431263 | X6: =U6/W6*1000 -> 21.705594 | Y6: =AVERAGEIFS(Data!$F:$F,Data!$A:$A,$B$27,Data!$B:$B,$B$3,Data!$C:$C,$T6) -> 76740 | Z6: =IF($Z$2=$Y$2,-$Y6,$X6) -> -76740 | AA6: #VALUE! | AB6: {=_FV(AA6,"Population")} -> 39431263
A7: Information | D7: 5 | E7: Construction | F7: =AVERAGEIFS(Data!$F:$F,Data!$A:$A,$B$27,Data!$B:$B,$E7) -> 63896.896 | G7: =IF($E7=$B$3,$F7,0) -> 63896.896 | I7: Manufacturing | J7: =SUMIFS(Data!$E:$E,Data!$A:$A,$B$27,Data!$B:$B,$I7) -> 12058694 | T7: Colorado | U7: =SUMIFS(Data!$E:$E,Data!$A:$A,$B$27,Data!$C:$C,$T7,Data!$B:$B,$B$3) -> 174730 | W7: 5957493 | X7: =U7/W7*1000 -> 29.329451 | Y7: =AVERAGEIFS(Data!$F:$F,Data!$A:$A,$B$27,Data!$B:$B,$B$3,Data!$C:$C,$T7) -> 68209 | Z7: =IF($Z$2=$Y$2,-$Y7,$X7) -> -68209 | AA7: #VALUE! | AB7: {=_FV(AA7,"Population")} -> 5957493
A8: Leisure & Hospitality | D8: 6 | E8: Natural Resources | F8: =AVERAGEIFS(Data!$F:$F,Data!$A:$A,$B$27,Data!$B:$B,$E8) -> 55605.938 | G8: =IF($E8=$B$3,$F8,0) -> 0 | I8: Finance | J8: =SUMIFS(Data!$E:$E,Data!$A:$A,$B$27,Data!$B:$B,$I8) -> 8142043 | T8: Connecticut | U8: =SUMIFS(Data!$E:$E,Data!$A:$A,$B$27,Data!$C:$C,$T8,Data!$B:$B,$B$3) -> 56915 | W8: 3675069 | X8: =U8/W8*1000 -> 15.486784 | Y8: =AVERAGEIFS(Data!$F:$F,Data!$A:$A,$B$27,Data!$B:$B,$B$3,Data!$C:$C,$T8) -> 75591 | Z8: =IF($Z$2=$Y$2,-$Y8,$X8) -> -75591 | AA8: #VALUE! | AB8: {=_FV(AA8,"Population")} -> 3675069
A9: Manufacturing | D9: 7 | E9: Education & Health | F9: =AVERAGEIFS(Data!$F:$F,Data!$A:$A,$B$27,Data!$B:$B,$E9) -> 53607.208 | G9: =IF($E9=$B$3,$F9,0) -> 0 | I9: Construction | J9: =SUMIFS(Data!$E:$E,Data!$A:$A,$B$27,Data!$B:$B,$I9) -> 7136444 | T9: Delaware | U9: =SUMIFS(Data!$E:$E,Data!$A:$A,$B$27,Data!$C:$C,$T9,Data!$B:$B,$B$3) -> 22403 | W9: 1051917 | X9: =U9/W9*1000 -> 21.297308 | Y9: =AVERAGEIFS(Data!$F:$F,Data!$A:$A,$B$27,Data!$B:$B,$B$3,Data!$C:$C,$T9) -> 64977 | Z9: =IF($Z$2=$Y$2,-$Y9,$X9) -> -64977 | AA9: #VALUE! | AB9: {=_FV(AA9,"Population")} -> 1051917
A10: Natural Resources | D10: 8 | E10: Trade & Transportation | F10: =AVERAGEIFS(Data!$F:$F,Data!$A:$A,$B$27,Data!$B:$B,$E10) -> 49366.812 | G10: =IF($E10=$B$3,$F10,0) -> 0 | I10: Other Services | J10: =SUMIFS(Data!$E:$E,Data!$A:$A,$B$27,Data!$B:$B,$I10) -> 3843699 | T10: Florida | U10: =SUMIFS(Data!$E:$E,Data!$A:$A,$B$27,Data!$C:$C,$T10,Data!$B:$B,$B$3) -> 561991 | W10: 23372215 | X10: =U10/W10*1000 -> 24.045261 | Y10: =AVERAGEIFS(Data!$F:$F,Data!$A:$A,$B$27,Data!$B:$B,$B$3,Data!$C:$C,$T10) -> 55910 | Z10: =IF($Z$2=$Y$2,-$Y10,$X10) -> -55910 | AA10: #VALUE! | AB10: {=_FV(AA10,"Population")} -> 23372215
A11: Other Services | D11: 9 | E11: Other Services | F11: =AVERAGEIFS(Data!$F:$F,Data!$A:$A,$B$27,Data!$B:$B,$E11) -> 40790.188 | G11: =IF($E11=$B$3,$F11,0) -> 0 | I11: Information | J11: =SUMIFS(Data!$E:$E,Data!$A:$A,$B$27,Data!$B:$B,$I11) -> 2677815 | T11: Georgia | U11: =SUMIFS(Data!$E:$E,Data!$A:$A,$B$27,Data!$C:$C,$T11,Data!$B:$B,$B$3) -> 200710 | W11: 11180878 | X11: =U11/W11*1000 -> 17.951184 | Y11: =AVERAGEIFS(Data!$F:$F,Data!$A:$A,$B$27,Data!$B:$B,$B$3,Data!$C:$C,$T11) -> 66214 | Z11: =IF($Z$2=$Y$2,-$Y11,$X11) -> -66214 | AA11: #VALUE! | AB11: {=_FV(AA11,"Population")} -> 11180878
A12: Trade & Transportation | D12: 10 | E12: Leisure & Hospitality | F12: =AVERAGEIFS(Data!$F:$F,Data!$A:$A,$B$27,Data!$B:$B,$E12) -> 23286.417 | G12: =IF($E12=$B$3,$F12,0) -> 0 | I12: Natural Resources | J12: =SUMIFS(Data!$E:$E,Data!$A:$A,$B$27,Data!$B:$B,$I12) -> 1762873 | T12: Idaho | U12: =SUMIFS(Data!$E:$E,Data!$A:$A,$B$27,Data!$C:$C,$T12,Data!$B:$B,$B$3) -> 53385 | W12: 2001619 | X12: =U12/W12*1000 -> 26.67091 | Y12: =AVERAGEIFS(Data!$F:$F,Data!$A:$A,$B$27,Data!$B:$B,$B$3,Data!$C:$C,$T12) -> 48649 | Z12: =IF($Z$2=$Y$2,-$Y12,$X12) -> -48649 | AA12: #VALUE! | AB12: {=_FV(AA12,"Population")} -> 2001619
D13: 11 | G13: =IFERROR(VLOOKUP(B13,$E$3:$F$12,2,FALSE),"") | T13: Illinois | U13: =SUMIFS(Data!$E:$E,Data!$A:$A,$B$27,Data!$C:$C,$T13,Data!$B:$B,$B$3) -> 216664 | W13: 12710158 | X13: =U13/W13*1000 -> 17.046523 | Y13: =AVERAGEIFS(Data!$F:$F,Data!$A:$A,$B$27,Data!$B:$B,$B$3,Data!$C:$C,$T13) -> 76581 | Z13: =IF($Z$2=$Y$2,-$Y13,$X13) -> -76581 | AA13: #VALUE! | AB13: {=_FV(AA13,"Population")} -> 12710158
A14: OR | D14: 12 | G14: =IFERROR(VLOOKUP(B14,$E$3:$F$12,2,FALSE),"") | T14: Indiana | U14: =SUMIFS(Data!$E:$E,Data!$A:$A,$B$27,Data!$C:$C,$T14,Data!$B:$B,$B$3) -> 144001 | W14: 6924275 | X14: =U14/W14*1000 -> 20.796545 | Y14: =AVERAGEIFS(Data!$F:$F,Data!$A:$A,$B$27,Data!$B:$B,$B$3,Data!$C:$C,$T14) -> 62619 | Z14: =IF($Z$2=$Y$2,-$Y14,$X14) -> -62619 | AA14: #VALUE! | AB14: {=_FV(AA14,"Population")} -> 6924275
A15: {=_xlfn._xlws.SORT(_xlfn.UNIQUE(Data!B2:B1919))} -> Business Services | D15: 13 | G15: =IFERROR(VLOOKUP(B15,$E$3:$F$12,2,FALSE),"") | T15: Iowa | U15: =SUMIFS(Data!$E:$E,Data!$A:$A,$B$27,Data!$C:$C,$T15,Data!$B:$B,$B$3) -> 76561 | W15: 3241488 | X15: =U15/W15*1000 -> 23.619091 | Y15: =AVERAGEIFS(Data!$F:$F,Data!$A:$A,$B$27,Data!$B:$B,$B$3,Data!$C:$C,$T15) -> 61831 | Z15: =IF($Z$2=$Y$2,-$Y15,$X15) -> -61831 | AA15: #VALUE! | AB15: {=_FV(AA15,"Population")} -> 3241488
A16: Construction | D16: 14 | G16: =IFERROR(VLOOKUP(B16,$E$3:$F$12,2,FALSE),"") | T16: Kansas | U16: =SUMIFS(Data!$E:$E,Data!$A:$A,$B$27,Data!$C:$C,$T16,Data!$B:$B,$B$3) -> 63118 | W16: 2970606 | X16: =U16/W16*1000 -> 21.247517 | Y16: =AVERAGEIFS(Data!$F:$F,Data!$A:$A,$B$27,Data!$B:$B,$B$3,Data!$C:$C,$T16) -> 59126 | Z16: =IF($Z$2=$Y$2,-$Y16,$X16) -> -59126 | AA16: #VALUE! | AB16: {=_FV(AA16,"Population")} -> 2970606
A17: Education & Health | D17: 15 | G17: =IFERROR(VLOOKUP(B17,$E$3:$F$12,2,FALSE),"") | T17: Kentucky | U17: =SUMIFS(Data!$E:$E,Data!$A:$A,$B$27,Data!$C:$C,$T17,Data!$B:$B,$B$3) -> 77924 | W17: 4588372 | X17: =U17/W17*1000 -> 16.98293 | Y17: =AVERAGEIFS(Data!$F:$F,Data!$A:$A,$B$27,Data!$B:$B,$B$3,Data!$C:$C,$T17) -> 58484 | Z17: =IF($Z$2=$Y$2,-$Y17,$X17) -> -58484 | AA17: #VALUE! | AB17: {=_FV(AA17,"Population")} -> 4588372
A18: Finance | D18: 16 | G18: =IFERROR(VLOOKUP(B18,$E$3:$F$12,2,FALSE),"") | T18: Louisiana | U18: =SUMIFS(Data!$E:$E,Data!$A:$A,$B$27,Data!$C:$C,$T18,Data!$B:$B,$B$3) -> 121521 | W18: 4597740 | X18: =U18/W18*1000 -> 26.430594 | Y18: =AVERAGEIFS(Data!$F:$F,Data!$A:$A,$B$27,Data!$B:$B,$B$3,Data!$C:$C,$T18) -> 65354 | Z18: =IF($Z$2=$Y$2,-$Y18,$X18) -> -65354 | AA18: #VALUE! | AB18: {=_FV(AA18,"Population")} -> 4597740
A19: Information | D19: 17 | G19: =IFERROR(VLOOKUP(B19,$E$3:$F$12,2,FALSE),"") | T19: Maine | U19: =SUMIFS(Data!$E:$E,Data!$A:$A,$B$27,Data!$C:$C,$T19,Data!$B:$B,$B$3) -> 30344 | W19: 1405012 | X19: =U19/W19*1000 -> 21.596969 | Y19: =AVERAGEIFS(Data!$F:$F,Data!$A:$A,$B$27,Data!$B:$B,$B$3,Data!$C:$C,$T19) -> 55607 | Z19: =IF($Z$2=$Y$2,-$Y19,$X19) -> -55607 | AA19: #VALUE! | AB19: {=_FV(AA19,"Population")} -> 1405012
A20: Leisure & Hospitality | D20: 18 | G20: =IFERROR(VLOOKUP(B20,$E$3:$F$12,2,FALSE),"") | T20: Maryland | U20: =SUMIFS(Data!$E:$E,Data!$A:$A,$B$27,Data!$C:$C,$T20,Data!$B:$B,$B$3) -> 160039 | W20: 6263220 | X20: =U20/W20*1000 -> 25.552192 | Y20: =AVERAGEIFS(Data!$F:$F,Data!$A:$A,$B$27,Data!$B:$B,$B$3,Data!$C:$C,$T20) -> 70642 | Z20: =IF($Z$2=$Y$2,-$Y20,$X20) -> -70642 | AA20: #VALUE! | AB20: {=_FV(AA20,"Population")} -> 6263220
A21: Manufacturing | D21: 19 | G21: =IFERROR(VLOOKUP(B21,$E$3:$F$12,2,FALSE),"") | T21: Massachusetts | U21: =SUMIFS(Data!$E:$E,Data!$A:$A,$B$27,Data!$C:$C,$T21,Data!$B:$B,$B$3) -> 152366 | W21: 7136171 | X21: =U21/W21*1000 -> 21.351226 | Y21: =AVERAGEIFS(Data!$F:$F,Data!$A:$A,$B$27,Data!$B:$B,$B$3,Data!$C:$C,$T21) -> 84958 | Z21: =IF($Z$2=$Y$2,-$Y21,$X21) -> -84958 | AA21: #VALUE! | AB21: {=_FV(AA21,"Population")} -> 7136171
A22: Natural Resources | D22: 20 | G22: =IFERROR(VLOOKUP(B22,$E$3:$F$12,2,FALSE),"") | T22: Michigan | U22: =SUMIFS(Data!$E:$E,Data!$A:$A,$B$27,Data!$C:$C,$T22,Data!$B:$B,$B$3) -> 164028 | W22: 10140459 | X22: =U22/W22*1000 -> 16.175599 | Y22: =AVERAGEIFS(Data!$F:$F,Data!$A:$A,$B$27,Data!$B:$B,$B$3,Data!$C:$C,$T22) -> 67631 | Z22: =IF($Z$2=$Y$2,-$Y22,$X22) -> -67631 | AA22: #VALUE! | AB22: {=_FV(AA22,"Population")} -> 10140459
A23: Other Services | D23: 21 | G23: =IFERROR(VLOOKUP(B23,$E$3:$F$12,2,FALSE),"") | T23: Minnesota | U23: =SUMIFS(Data!$E:$E,Data!$A:$A,$B$27,Data!$C:$C,$T23,Data!$B:$B,$B$3) -> 123866 | W23: 5793151 | X23: =U23/W23*1000 -> 21.381455 | Y23: =AVERAGEIFS(Data!$F:$F,Data!$A:$A,$B$27,Data!$B:$B,$B$3,Data!$C:$C,$T23) -> 72942 | Z23: =IF($Z$2=$Y$2,-$Y23,$X23) -> -72942 | AA23: #VALUE! | AB23: {=_FV(AA23,"Population")} -> 5793151
A24: Trade & Transportation | D24: 22 | G24: =IFERROR(VLOOKUP(B24,$E$3:$F$12,2,FALSE),"") | T24: Mississippi | U24: =SUMIFS(Data!$E:$E,Data!$A:$A,$B$27,Data!$C:$C,$T24,Data!$B:$B,$B$3) -> 43888 | W24: 2943045 | X24: =U24/W24*1000 -> 14.912446 | Y24: =AVERAGEIFS(Data!$F:$F,Data!$A:$A,$B$27,Data!$B:$B,$B$3,Data!$C:$C,$T24) -> 53779 | Z24: =IF($Z$2=$Y$2,-$Y24,$X24) -> -53779 | AA24: #VALUE! | AB24: {=_FV(AA24,"Population")} -> 2943045
T25: Missouri | U25: =SUMIFS(Data!$E:$E,Data!$A:$A,$B$27,Data!$C:$C,$T25,Data!$B:$B,$B$3) -> 126375 | W25: 6245466 | X25: =U25/W25*1000 -> 20.234679 | Y25: =AVERAGEIFS(Data!$F:$F,Data!$A:$A,$B$27,Data!$B:$B,$B$3,Data!$C:$C,$T25) -> 64664 | Z25: =IF($Z$2=$Y$2,-$Y25,$X25) -> -64664 | AA25: #VALUE! | AB25: {=_FV(AA25,"Population")} -> 6245466
A26: DATE FILTER | I26: EMPLOYEES BY INDUSTRY FOR CURRENT YEAR (CLEAN) | T26: Montana | U26: =SUMIFS(Data!$E:$E,Data!$A:$A,$B$27,Data!$C:$C,$T26,Data!$B:$B,$B$3) -> 30793 | W26: 1137233 | X26: =U26/W26*1000 -> 27.077125 | Y26: =AVERAGEIFS(Data!$F:$F,Data!$A:$A,$B$27,Data!$B:$B,$B$3,Data!$C:$C,$T26) -> 55897 | Z26: =IF($Z$2=$Y$2,-$Y26,$X26) -> -55897 | AA26: #VALUE! | AB26: {=_FV(AA26,"Population")} -> 1137233
A27: Current Year: | B27: 2020 | I27: Industry | J27: Employees | T27: Nebraska | U27: =SUMIFS(Data!$E:$E,Data!$A:$A,$B$27,Data!$C:$C,$T27,Data!$B:$B,$B$3) -> 55249 | W27: 2005465 | X27: =U27/W27*1000 -> 27.549222 | Y27: =AVERAGEIFS(Data!$F:$F,Data!$A:$A,$B$27,Data!$B:$B,$B$3,Data!$C:$C,$T27) -> 56548 | Z27: =IF($Z$2=$Y$2,-$Y27,$X27) -> -56548 | AA27: #VALUE! | AB27: {=_FV(AA27,"Population")} -> 2005465
I28: =B3 -> Construction | J28: =VLOOKUP(B3,$I$3:$J$12,2,FALSE) -> 7136444 | T28: Nevada | U28: =SUMIFS(Data!$E:$E,Data!$A:$A,$B$27,Data!$C:$C,$T28,Data!$B:$B,$B$3) -> 93450 | W28: 3267467 | X28: =U28/W28*1000 -> 28.600136 | Y28: =AVERAGEIFS(Data!$F:$F,Data!$A:$A,$B$27,Data!$B:$B,$B$3,Data!$C:$C,$T28) -> 67902 | Z28: =IF($Z$2=$Y$2,-$Y28,$X28) -> -67902 | AA28: #VALUE! | AB28: {=_FV(AA28,"Population")} -> 3267467
I29: Others | J29: =SUM(J3:J12)-J28 -> 109512895 | T29: New Hampshire | U29: =SUMIFS(Data!$E:$E,Data!$A:$A,$B$27,Data!$C:$C,$T29,Data!$B:$B,$B$3) -> 27866 | W29: 1409032 | X29: =U29/W29*1000 -> 19.776698 | Y29: =AVERAGEIFS(Data!$F:$F,Data!$A:$A,$B$27,Data!$B:$B,$B$3,Data!$C:$C,$T29) -> 68870 | Z29: =IF($Z$2=$Y$2,-$Y29,$X29) -> -68870 | AA29: #VALUE! | AB29: {=_FV(AA29,"Population")} -> 1409032
A30: MAP FILTER | T30: New Jersey | U30: =SUMIFS(Data!$E:$E,Data!$A:$A,$B$27,Data!$C:$C,$T30,Data!$B:$B,$B$3) -> 151469 | W30: 9288994 | X30: =U30/W30*1000 -> 16.306287 | Y30: =AVERAGEIFS(Data!$F:$F,Data!$A:$A,$B$27,Data!$B:$B,$B$3,Data!$C:$C,$T30) -> 77924 | Z30: =IF($Z$2=$Y$2,-$Y30,$X30) -> -77924 | AA30: #VALUE! | AB30: {=_FV(AA30,"Population")} -> 9288994
A31: Metric: | B31: =IF(Dashboard!$I$4=1,'Data prep'!$Y$2,'Data prep'!$X$2) -> Average wages | T31: New Mexico | U31: =SUMIFS(Data!$E:$E,Data!$A:$A,$B$27,Data!$C:$C,$T31,Data!$B:$B,$B$3) -> 48577 | W31: 2130256 | X31: =U31/W31*1000 -> 22.803363 | Y31: =AVERAGEIFS(Data!$F:$F,Data!$A:$A,$B$27,Data!$B:$B,$B$3,Data!$C:$C,$T31) -> 53439 | Z31: =IF($Z$2=$Y$2,-$Y31,$X31) -> -53439 | AA31: #VALUE! | AB31: {=_FV(AA31,"Population")} -> 2130256
T32: New York | U32: =SUMIFS(Data!$E:$E,Data!$A:$A,$B$27,Data!$C:$C,$T32,Data!$B:$B,$B$3) -> 361821 | W32: 20201249 | X32: =U32/W32*1000 -> 17.910823 | Y32: =AVERAGEIFS(Data!$F:$F,Data!$A:$A,$B$27,Data!$B:$B,$B$3,Data!$C:$C,$T32) -> 78199 | Z32: =IF($Z$2=$Y$2,-$Y32,$X32) -> -78199 | AA32: #VALUE! | AB32: {=_FV(AA32,"Population")} -> 20201249
T33: North Carolina | U33: =SUMIFS(Data!$E:$E,Data!$A:$A,$B$27,Data!$C:$C,$T33,Data!$B:$B,$B$3) -> 229369 | W33: 11046024 | X33: =U33/W33*1000 -> 20.764847 | Y33: =AVERAGEIFS(Data!$F:$F,Data!$A:$A,$B$27,Data!$B:$B,$B$3,Data!$C:$C,$T33) -> 59177 | Z33: =IF($Z$2=$Y$2,-$Y33,$X33) -> -59177 | AA33: #VALUE! | AB33: {=_FV(AA33,"Population")} -> 11046024
T34: North Dakota | U34: =SUMIFS(Data!$E:$E,Data!$A:$A,$B$27,Data!$C:$C,$T34,Data!$B:$B,$B$3) -> 25364 | W34: 796568 | X34: =U34/W34*1000 -> 31.8416 | Y34: =AVERAGEIFS(Data!$F:$F,Data!$A:$A,$B$27,Data!$B:$B,$B$3,Data!$C:$C,$T34) -> 66729 | Z34: =IF($Z$2=$Y$2,-$Y34,$X34) -> -66729 | AA34: #VALUE! | AB34: {=_FV(AA34,"Population")} -> 796568
T35: Ohio | U35: =SUMIFS(Data!$E:$E,Data!$A:$A,$B$27,Data!$C:$C,$T35,Data!$B:$B,$B$3) -> 218531 | W35: 11883304 | X35: =U35/W35*1000 -> 18.389751 | Y35: =AVERAGEIFS(Data!$F:$F,Data!$A:$A,$B$27,Data!$B:$B,$B$3,Data!$C:$C,$T35) -> 65104 | Z35: =IF($Z$2=$Y$2,-$Y35,$X35) -> -65104 | AA35: #VALUE! | AB35: {=_FV(AA35,"Population")} -> 11883304
T36: Oklahoma | U36: =SUMIFS(Data!$E:$E,Data!$A:$A,$B$27,Data!$C:$C,$T36,Data!$B:$B,$B$3) -> 78772 | W36: 3959353 | X36: =U36/W36*1000 -> 19.89517 | Y36: =AVERAGEIFS(Data!$F:$F,Data!$A:$A,$B$27,Data!$B:$B,$B$3,Data!$C:$C,$T36) -> 55099 | Z36: =IF($Z$2=$Y$2,-$Y36,$X36) -> -55099 | AA36: #VALUE! | AB36: {=_FV(AA36,"Population")} -> 3959353
T37: Oregon | U37: =SUMIFS(Data!$E:$E,Data!$A:$A,$B$27,Data!$C:$C,$T37,Data!$B:$B,$B$3) -> 107568 | W37: 4272371 | X37: =U37/W37*1000 -> 25.177589 | Y37: =AVERAGEIFS(Data!$F:$F,Data!$A:$A,$B$27,Data!$B:$B,$B$3,Data!$C:$C,$T37) -> 66876 | Z37: =IF($Z$2=$Y$2,-$Y37,$X37) -> -66876 | AA37: #VALUE! | AB37: {=_FV(AA37,"Population")} -> 4272371
T38: Pennsylvania | U38: =SUMIFS(Data!$E:$E,Data!$A:$A,$B$27,Data!$C:$C,$T38,Data!$B:$B,$B$3) -> 241570 | W38: 13078751 | X38: =U38/W38*1000 -> 18.470418 | Y38: =AVERAGEIFS(Data!$F:$F,Data!$A:$A,$B$27,Data!$B:$B,$B$3,Data!$C:$C,$T38) -> 70639 | Z38: =IF($Z$2=$Y$2,-$Y38,$X38) -> -70639 | AA38: #VALUE! | AB38: {=_FV(AA38,"Population")} -> 13078751
T39: Rhode Island | U39: =SUMIFS(Data!$E:$E,Data!$A:$A,$B$27,Data!$C:$C,$T39,Data!$B:$B,$B$3) -> 18924 | W39: 1112308 | X39: =U39/W39*1000 -> 17.013273 | Y39: =AVERAGEIFS(Data!$F:$F,Data!$A:$A,$B$27,Data!$B:$B,$B$3,Data!$C:$C,$T39) -> 66955 | Z39: =IF($Z$2=$Y$2,-$Y39,$X39) -> -66955 | AA39: #VALUE! | AB39: {=_FV(AA39,"Population")} -> 1112308
T40: South Carolina | U40: =SUMIFS(Data!$E:$E,Data!$A:$A,$B$27,Data!$C:$C,$T40,Data!$B:$B,$B$3) -> 103647 | W40: 5478831 | X40: =U40/W40*1000 -> 18.917722 | Y40: =AVERAGEIFS(Data!$F:$F,Data!$A:$A,$B$27,Data!$B:$B,$B$3,Data!$C:$C,$T40) -> 57906 | Z40: =IF($Z$2=$Y$2,-$Y40,$X40) -> -57906 | AA40: #VALUE! | AB40: {=_FV(AA40,"Population")} -> 5478831
...

Sheet Tips 
A1: Graph | B1: Information | H1: 2020
A2: Bar | B2: gap width 85% | H2: 2019
A3: Doughnat | B3: Doughnat hole size 60% | H3: 2018
H4: 2017
